<h1>
 Title: Exception 2018Sp
</h1>
<h3>
 Author: Anonymous
</h3>
<h3>
 Date: 2022-03-08T07:44:15.946907+11:00
</h3>
<h3>
 Category: Exams
</h3>
<h3>
 Vote Count: 0
</h3>
<p>
 Hi, I was wondering for foo(0,0), why are we not executing the catch(ArithmeticException e) explicitly as( 1,5,6,8 ) .
</p>
<p>
 Instead, the answer key left the answer as "1, Arithmetic Exception".
</p>
<figure>
 <image height="535.6536585365853" src="https://static.us.edusercontent.com/files/pBQBtBFCDsGhVWYuVymTOH8y" width="581"/>
</figure>
<h3>
 ----------- REPLIES -----------
</h3>
<div style="text-indent: 2em;">
 <h3>
  Author: Tomer Shamir (staff)
 </h3>
 <h3>
  Vote Count: 0
 </h3>
 <p>
  Since the statement
  <code>
   int res = a / (b * 5)
  </code>
  is outside the try block of the try-catch statement, the ArithmeticException is not caught, so this call first prints 1 and then throws an ArithmeticException.
 </p>
 <h3>
  ------------------------------------
 </h3>
 <div style="text-indent: 4em;">
  <h3>
   Author: Anonymous
  </h3>
  <h3>
   Vote Count: 0
  </h3>
  <p>
   ohh ok thanks!!
  </p>
  <h3>
   ------------------------------------
  </h3>
 </div>
</div>