<h1>
 Title: try catch
</h1>
<h3>
 Author: Anonymous
</h3>
<h3>
 Date: 2022-03-09T03:53:35.550585+11:00
</h3>
<h3>
 Category: Exams
</h3>
<h3>
 Vote Count: 0
</h3>
<p>
 When calling foo(-1, -1), why does the program still goes to catch Exception e and print "8", rather than terminate when throwing the new IllegalArugumentException?
</p>
<p>
 Thank you.
</p>
<figure>
 <image height="380" src="https://static.us.edusercontent.com/files/cOZ9QNR2kJRqcum5EPeKqddy" width="481"/>
</figure>
<h3>
 ----------- REPLIES -----------
</h3>
<div style="text-indent: 2em;">
 <h3>
  Author: Bahaa Kotb (student)
 </h3>
 <h3>
  Vote Count: 1
 </h3>
 <p>
  It does throw an IllegalArgumentException, which is a subclass of Exception so itâ€™s caught and prints 7 then 8.
 </p>
 <h3>
  ------------------------------------
 </h3>
 <div style="text-indent: 4em;">
  <h3>
   Author: Bahaa Kotb (student)
  </h3>
  <h3>
   Vote Count: 0
  </h3>
  <p>
   printing 8 is after the whole try catch block
  </p>
  <h3>
   ------------------------------------
  </h3>
  <div style="text-indent: 4em;">
   <h3>
    Author: Anonymous
   </h3>
   <h3>
    Vote Count: 0
   </h3>
   <p>
    ohh i got it thanks!!
   </p>
   <h3>
    ------------------------------------
   </h3>
  </div>
 </div>
</div>