<h1>
 Title: try catch
</h1>
<h3>
 Author: Anonymous
</h3>
<h3>
 Date: 2022-03-09T03:53:35.550585+11:00
</h3>
<h3>
 Category: Exams
</h3>
<h3>
 Vote Count: 0
</h3>
<document version="2.0">
 <paragraph>
  When calling foo(-1, -1), why does the program still goes to catch Exception e and print "8", rather than terminate when throwing the new IllegalArugumentException?
 </paragraph>
 <paragraph>
  Thank you.
 </paragraph>
 <figure>
  <image height="380" src="https://static.us.edusercontent.com/files/cOZ9QNR2kJRqcum5EPeKqddy" width="481"/>
 </figure>
</document>
<h3>
 ----------- REPLIES -----------
</h3>
<h3>
 Author: Bahaa Kotb (student)
</h3>
<h3>
 Vote Count: 1
</h3>
<document version="1.0">
 <paragraph>
  It does throw an IllegalArgumentException, which is a subclass of Exception so itâ€™s caught and prints 7 then 8.
 </paragraph>
</document>
<h3>
 ------------------------------------
</h3>
<h3>
 Author: Anonymous
</h3>
<h3>
 Vote Count: 0
</h3>
<document version="2.0">
 <paragraph>
  ohh i got it thanks!!
 </paragraph>
</document>
<h3>
 ------------------------------------
</h3>
<h3>
 Author: Bahaa Kotb (student)
</h3>
<h3>
 Vote Count: 0
</h3>
<document version="1.0">
 <paragraph>
  printing 8 is after the whole try catch block
 </paragraph>
</document>
<h3>
 ------------------------------------
</h3>