<h1>
 Title: Catch Block
</h1>
<h3>
 Author: Anonymous
</h3>
<h3>
 Date: 2021-09-12T01:11:43.347844+10:00
</h3>
<h3>
 Category: General
</h3>
<h3>
 Vote Count: 0
</h3>
<document version="2.0">
 <paragraph>
  Can catch blocks catch exceptions in each other?
 </paragraph>
 <paragraph>
  In other words, can a catch block in the same try-catch block, catch an exception thrown in the catch block above it?
 </paragraph>
</document>
<h3>
 ----------- REPLIES -----------
</h3>
<h3>
 Author: David Gries (admin)
</h3>
<h3>
 Vote Count: 0
</h3>
<document version="2.0">
 <paragraph>
  No. That it not how it works.
 </paragraph>
 <paragraph>
  If you read carefully how a try-statement is executed, you could answer that question yourself.
 </paragraph>
 <paragraph>
  Only objects thrown in the try-clause can be caught in a catch block.
 </paragraph>
</document>
<h3>
 ------------------------------------
</h3>