<h1>
 Title: If a try-block throws a "New ArtithmeticException()" but there's no catch block implemented to deal with that, does the exception leave the try-statement thrown back to the method call?
</h1>
<h3>
 Author: Anonymous
</h3>
<h3>
 Date: 2021-10-06T02:11:57.194233+11:00
</h3>
<h3>
 Category: General
</h3>
<h3>
 Vote Count: 0
</h3>
<document version="2.0">
 <paragraph>
  I am curious what would happen if a catch-block was not implemented to deal with a certain exception
 </paragraph>
</document>
<h3>
 ----------- REPLIES -----------
</h3>
<h3>
 Author: Varun Gande (student)
</h3>
<h3>
 Vote Count: 0
</h3>
<document version="2.0">
 <paragraph>
  Since there's no catch block to catch the thrown ArithmeticException, the Arithmetic Exception will be thrown to the call of whatever method implements the try statement.
 </paragraph>
</document>
<h3>
 ------------------------------------
</h3>
<h3>
 Author: David Gries (admin)
</h3>
<h3>
 Vote Count: 0
</h3>
<document version="2.0">
 <paragraph>
  The answer is given inn JavaHYperText, where is explains how a try-statement is executed. Please read that.
 </paragraph>
</document>
<h3>
 ------------------------------------
</h3>